---
title: "深入理解 Python 中的 assert array of exceptions"
description: "在 Python 编程中，异常处理是确保程序稳健运行的重要部分。而 `assert array of exceptions` 并不是 Python 内置的标准术语，但我们可以将其理解为针对一系列异常情况的断言处理。这在编写单元测试、验证输入以及确保程序逻辑的正确性方面都非常有用。本文将详细介绍如何在 Python 中处理和使用这一概念。"
date: 2025-04-06
categories: ["python"]
last_modified_at: 2025-04-06
cascade:
  - type: docs
---


## 简介
在 Python 编程中，异常处理是确保程序稳健运行的重要部分。而 `assert array of exceptions` 并不是 Python 内置的标准术语，但我们可以将其理解为针对一系列异常情况的断言处理。这在编写单元测试、验证输入以及确保程序逻辑的正确性方面都非常有用。本文将详细介绍如何在 Python 中处理和使用这一概念。

<!-- more -->
## 目录
1. 基础概念
2. 使用方法
3. 常见实践
4. 最佳实践
5. 小结
6. 参考资料

## 基础概念
### 断言（Assertion）
在 Python 中，`assert` 语句用于调试目的。它检查一个表达式，如果表达式为真，则程序继续执行；如果表达式为假，则会抛出 `AssertionError` 异常。例如：
```python
x = 10
assert x > 5, "x 应该大于 5"
```
### 异常（Exception）
Python 有许多内置的异常类型，如 `ZeroDivisionError`、`TypeError`、`ValueError` 等。当程序执行遇到错误情况时，会抛出相应的异常。异常处理允许我们捕获并处理这些错误，防止程序意外终止。例如：
```python
try:
    result = 10 / 0
except ZeroDivisionError:
    print("不能除以零")
```

### 组合理解
“assert array of exceptions” 意味着我们可以在一个逻辑中处理多个可能的异常情况，通过断言确保程序在遇到这些异常时的行为符合预期。

## 使用方法
### 单一断言处理多个异常
在 `try` 块中，我们可以使用一个 `assert` 语句来处理多个可能的异常情况。例如，考虑一个函数，它接收一个数字并进行一些操作：
```python
def divide_numbers(a, b):
    try:
        assert b != 0, "除数不能为零"
        result = a / b
        assert isinstance(result, (int, float)), "结果应该是数字类型"
        return result
    except AssertionError as ae:
        print(f"断言错误: {ae}")
    except Exception as e:
        print(f"其他错误: {e}")


print(divide_numbers(10, 0))
```
### 针对不同异常类型分别处理
我们也可以针对不同的异常类型进行分别处理，使用多个 `except` 块：
```python
def divide_numbers(a, b):
    try:
        result = a / b
    except ZeroDivisionError:
        print("除数不能为零")
    except TypeError:
        print("输入类型错误")
    else:
        return result


print(divide_numbers(10, "2"))
```

## 常见实践
### 单元测试中的应用
在单元测试框架（如 `unittest`）中，我们经常使用断言来验证函数的输出是否符合预期。例如：
```python
import unittest


def add_numbers(a, b):
    return a + b


class TestAddNumbers(unittest.TestCase):
    def test_add_numbers(self):
        result = add_numbers(2, 3)
        self.assertEqual(result, 5)


if __name__ == '__main__':
    unittest.main()
```
### 输入验证
在函数入口处，我们可以使用断言和异常处理来验证输入的合法性。例如：
```python
def calculate_area(radius):
    assert isinstance(radius, (int, float)), "半径必须是数字类型"
    assert radius > 0, "半径必须是正数"
    return 3.14 * radius ** 2


print(calculate_area(-2))
```

## 最佳实践
### 清晰的错误信息
在断言和异常处理中，提供清晰的错误信息非常重要，这有助于调试和理解问题所在。例如：
```python
def convert_to_int(value):
    try:
        num = int(value)
        assert num > 0, f"{value} 转换为整数后应该是正数"
        return num
    except ValueError:
        print(f"{value} 无法转换为整数")
    except AssertionError as ae:
        print(ae)


print(convert_to_int("-5"))
```

### 分层处理
对于复杂的程序逻辑，可以采用分层的异常处理方式。在高层捕获一般性的异常，在底层处理特定的业务逻辑异常。例如：
```python
def outer_function():
    try:
        inner_function()
    except Exception as e:
        print(f"外层函数捕获到异常: {e}")


def inner_function():
    try:
        result = 10 / 0
    except ZeroDivisionError:
        print("内层函数捕获到除数为零的异常")
        raise


outer_function()
```

## 小结
在 Python 中，处理 `assert array of exceptions` 涉及到断言和异常处理的结合使用。通过合理运用断言来验证假设，以及通过异常处理捕获和处理错误，我们可以编写更健壮、易于调试的代码。在实践中，单元测试和输入验证是常见的应用场景，而遵循清晰的错误信息和分层处理等最佳实践可以提升代码的质量和可维护性。

## 参考资料
- [Python 官方文档 - 异常处理](https://docs.python.org/3/tutorial/errors.html)
- [unittest 官方文档](https://docs.python.org/3/library/unittest.html)