---
title: "Python 中 try except 块里 continue 的作用解析"
description: "在 Python 编程中，`try except` 结构用于捕获和处理异常，而 `continue` 语句用于控制循环的流程。当 `continue` 出现在 `try except` 块中时，它的行为会结合异常处理机制产生一些独特的效果。理解 `try except` 块里 `continue` 的作用，能帮助开发者更灵活、高效地处理程序中的错误和控制循环执行逻辑，这对于编写健壮的 Python 代码至关重要。"
date: 2025-04-13
categories: ["python"]
last_modified_at: 2025-04-13
cascade:
  - type: docs
---


## 简介
在 Python 编程中，`try except` 结构用于捕获和处理异常，而 `continue` 语句用于控制循环的流程。当 `continue` 出现在 `try except` 块中时，它的行为会结合异常处理机制产生一些独特的效果。理解 `try except` 块里 `continue` 的作用，能帮助开发者更灵活、高效地处理程序中的错误和控制循环执行逻辑，这对于编写健壮的 Python 代码至关重要。

<!-- more -->
## 目录
1. **基础概念**
2. **使用方法**
3. **常见实践**
4. **最佳实践**
5. **小结**
6. **参考资料**

## 基础概念
### `try except` 结构
`try except` 结构用于检测 `try` 块中的代码是否有异常发生。如果 `try` 块中的代码引发了异常，程序流程会立即跳转到对应的 `except` 块中执行处理代码。例如：
```python
try:
    result = 10 / 0  # 这会引发一个 ZeroDivisionError 异常
except ZeroDivisionError:
    print("不能除以零")
```
### `continue` 语句
`continue` 语句用于跳过当前循环迭代的剩余部分，并开始下一次迭代。例如在一个简单的 `for` 循环中：
```python
for i in range(5):
    if i == 2:
        continue
    print(i)
```
这段代码会打印出 `0`、`1`、`3`、`4`，跳过了 `i == 2` 的那次迭代。

### 结合 `try except` 和 `continue`
当 `continue` 出现在 `try except` 块中时，它可以在处理完异常后，跳过当前循环迭代的剩余部分，直接进入下一次迭代。这在需要对循环中的每个元素进行操作，并且某些操作可能引发异常，但又不想因为这些异常而中断整个循环的情况下非常有用。

## 使用方法
### 在 `for` 循环中使用
```python
data = [1, 0, 2, 0, 3]
for num in data:
    try:
        result = 10 / num
        print(f"10 除以 {num} 结果是: {result}")
    except ZeroDivisionError:
        print(f"不能除以 {num}")
        continue
```
在这个例子中，当 `num` 为 `0` 时，会引发 `ZeroDivisionError` 异常，`except` 块捕获异常并打印提示信息，然后通过 `continue` 跳过本次循环剩余部分，进入下一次迭代。

### 在 `while` 循环中使用
```python
count = 0
while count < 5:
    try:
        value = 1 / (count - 2)
        print(f"1 除以 {count - 2} 结果是: {value}")
    except ZeroDivisionError:
        print(f"不能除以 {count - 2}")
        count += 1
        continue
    count += 1
```
这里，当 `count` 为 `2` 时会引发 `ZeroDivisionError` 异常，`except` 块处理异常后，通过 `continue` 直接进入下一次循环条件判断，继续执行循环。

## 常见实践
### 数据处理中的异常跳过
在处理大量数据时，可能会遇到部分数据导致的异常情况。例如读取文件中的数字进行计算：
```python
file_content = "1, 0, 2, abc, 3"
nums = file_content.split(', ')
for num_str in nums:
    try:
        num = int(num_str)
        result = 10 / num
        print(f"10 除以 {num} 结果是: {result}")
    except (ZeroDivisionError, ValueError):
        print(f"{num_str} 无法正常处理")
        continue
```
这里使用 `continue` 跳过无法转换为数字或导致除零错误的数据，继续处理下一个数据。

### 网络请求重试
在进行网络请求时，可能会因为网络波动等原因引发异常。可以使用 `try except` 和 `continue` 实现重试机制：
```python
import requests

urls = ["http://example.com", "http://nonexistent-site.com", "http://another-example.com"]
for url in urls:
    try:
        response = requests.get(url)
        response.raise_for_status()
        print(f"成功获取 {url} 的内容")
    except requests.RequestException as e:
        print(f"获取 {url} 时出错: {e}")
        continue
```
当某个 URL 请求失败时，捕获异常并打印错误信息，然后通过 `continue` 尝试下一个 URL 的请求。

## 最佳实践
### 精准的异常捕获
只捕获可能出现的特定异常，避免捕获过于宽泛的异常类型。这样可以确保只有真正需要处理的异常才会被处理，并且能更清晰地定位和解决问题。例如：
```python
try:
    # 可能引发特定异常的代码
    pass
except SpecificException:
    # 处理特定异常的代码
    continue
```

### 记录异常信息
在处理异常时，最好记录详细的异常信息，以便后续调试和分析。可以使用 Python 的日志模块：
```python
import logging

logging.basicConfig(level=logging.ERROR)

try:
    # 可能引发异常的代码
    pass
except SomeException as e:
    logging.error(f"发生异常: {e}")
    continue
```

### 避免无限循环
在使用 `continue` 时，要确保循环有退出条件，避免因为异常处理导致无限循环。例如在 `while` 循环中，要保证在每次迭代中某些条件会发生变化，使循环最终能够结束。

## 小结
在 Python 的 `try except` 块中使用 `continue`，可以在处理异常后灵活控制循环流程，跳过当前迭代的剩余部分继续执行下一次迭代。这在数据处理、网络请求等多种场景下非常实用。通过精准捕获异常、记录异常信息以及避免无限循环等最佳实践，可以编写更健壮、可靠的 Python 代码。

## 参考资料
- [Python 官方文档](https://docs.python.org/3/)
- 《Python 核心编程》